[2025-01-11T12:03:38.691+0000] {local_task_job_runner.py:123} INFO - ::group::Pre task execution logs
[2025-01-11T12:03:38.703+0000] {taskinstance.py:2613} INFO - Dependencies all met for dep_context=non-requeueable deps ti=<TaskInstance: dynamic_task_mapping_with_fixed_chunk_size.fetch_messages_from_bq manual__2025-01-11T12:03:33.153528+00:00 [queued]>
[2025-01-11T12:03:38.709+0000] {taskinstance.py:2613} INFO - Dependencies all met for dep_context=requeueable deps ti=<TaskInstance: dynamic_task_mapping_with_fixed_chunk_size.fetch_messages_from_bq manual__2025-01-11T12:03:33.153528+00:00 [queued]>
[2025-01-11T12:03:38.710+0000] {taskinstance.py:2866} INFO - Starting attempt 1 of 1
[2025-01-11T12:03:38.719+0000] {taskinstance.py:2889} INFO - Executing <Task(_PythonDecoratedOperator): fetch_messages_from_bq> on 2025-01-11 12:03:33.153528+00:00
[2025-01-11T12:03:38.761+0000] {standard_task_runner.py:72} INFO - Started process 283 to run task
[2025-01-11T12:03:38.782+0000] {standard_task_runner.py:104} INFO - Running: ['***', 'tasks', 'run', 'dynamic_task_mapping_with_fixed_chunk_size', 'fetch_messages_from_bq', 'manual__2025-01-11T12:03:33.153528+00:00', '--job-id', '741', '--raw', '--subdir', 'DAGS_FOLDER/experiments/dynamic_task_mapping_parralel_dag.py', '--cfg-path', '/tmp/tmp9dg2fns8']
[2025-01-11T12:03:38.796+0000] {standard_task_runner.py:105} INFO - Job 741: Subtask fetch_messages_from_bq
[2025-01-11T12:03:38.856+0000] {task_command.py:467} INFO - Running <TaskInstance: dynamic_task_mapping_with_fixed_chunk_size.fetch_messages_from_bq manual__2025-01-11T12:03:33.153528+00:00 [running]> on host a2978c5b6b3a
[2025-01-11T12:03:39.285+0000] {taskinstance.py:3132} INFO - Exporting env vars: AIRFLOW_CTX_DAG_OWNER='***' AIRFLOW_CTX_DAG_ID='dynamic_task_mapping_with_fixed_chunk_size' AIRFLOW_CTX_TASK_ID='fetch_messages_from_bq' AIRFLOW_CTX_EXECUTION_DATE='2025-01-11T12:03:33.153528+00:00' AIRFLOW_CTX_TRY_NUMBER='1' AIRFLOW_CTX_DAG_RUN_ID='manual__2025-01-11T12:03:33.153528+00:00'
[2025-01-11T12:03:39.295+0000] {taskinstance.py:731} INFO - ::endgroup::
[2025-01-11T12:03:39.317+0000] {taskinstance.py:3311} ERROR - Task failed with exception
Traceback (most recent call last):
  File "/home/airflow/.local/lib/python3.10/site-packages/airflow/models/taskinstance.py", line 767, in _execute_task
    result = _execute_callable(context=context, **execute_callable_kwargs)
  File "/home/airflow/.local/lib/python3.10/site-packages/airflow/models/taskinstance.py", line 733, in _execute_callable
    return ExecutionCallableRunner(
  File "/home/airflow/.local/lib/python3.10/site-packages/airflow/utils/operator_helpers.py", line 252, in run
    return self.func(*args, **kwargs)
  File "/home/airflow/.local/lib/python3.10/site-packages/airflow/models/baseoperator.py", line 417, in wrapper
    return func(self, *args, **kwargs)
  File "/home/airflow/.local/lib/python3.10/site-packages/airflow/decorators/base.py", line 266, in execute
    return_value = super().execute(context)
  File "/home/airflow/.local/lib/python3.10/site-packages/airflow/models/baseoperator.py", line 417, in wrapper
    return func(self, *args, **kwargs)
  File "/home/airflow/.local/lib/python3.10/site-packages/airflow/operators/python.py", line 238, in execute
    return_value = self.execute_callable()
  File "/home/airflow/.local/lib/python3.10/site-packages/airflow/operators/python.py", line 256, in execute_callable
    return runner.run(*self.op_args, **self.op_kwargs)
  File "/home/airflow/.local/lib/python3.10/site-packages/airflow/utils/operator_helpers.py", line 252, in run
    return self.func(*args, **kwargs)
  File "/opt/airflow/dags/experiments/dynamic_task_mapping_parralel_dag.py", line 25, in fetch_messages_from_bq
    client = bigquery.Client(project=BIGQUERY_CONN_ID)
  File "/home/airflow/.local/lib/python3.10/site-packages/google/cloud/bigquery/client.py", line 241, in __init__
    super(Client, self).__init__(
  File "/home/airflow/.local/lib/python3.10/site-packages/google/cloud/client/__init__.py", line 321, in __init__
    Client.__init__(
  File "/home/airflow/.local/lib/python3.10/site-packages/google/cloud/client/__init__.py", line 178, in __init__
    credentials, _ = google.auth.default(scopes=scopes)
  File "/home/airflow/.local/lib/python3.10/site-packages/google/auth/_default.py", line 659, in default
    credentials, project_id = checker()
  File "/home/airflow/.local/lib/python3.10/site-packages/google/auth/_default.py", line 652, in <lambda>
    lambda: _get_explicit_environ_credentials(quota_project_id=quota_project_id),
  File "/home/airflow/.local/lib/python3.10/site-packages/google/auth/_default.py", line 271, in _get_explicit_environ_credentials
    credentials, project_id = load_credentials_from_file(
  File "/home/airflow/.local/lib/python3.10/site-packages/google/auth/_default.py", line 114, in load_credentials_from_file
    raise exceptions.DefaultCredentialsError(
google.auth.exceptions.DefaultCredentialsError: File /opt/gcp/config/legacy_credentials/fadhel.ijlal@ceritanyaimel/adc.json was not found.
[2025-01-11T12:03:39.341+0000] {taskinstance.py:1225} INFO - Marking task as FAILED. dag_id=dynamic_task_mapping_with_fixed_chunk_size, task_id=fetch_messages_from_bq, run_id=manual__2025-01-11T12:03:33.153528+00:00, execution_date=20250111T120333, start_date=20250111T120338, end_date=20250111T120339
[2025-01-11T12:03:39.367+0000] {taskinstance.py:340} INFO - ::group::Post task execution logs
[2025-01-11T12:03:39.367+0000] {standard_task_runner.py:124} ERROR - Failed to execute job 741 for task fetch_messages_from_bq (File /opt/gcp/config/legacy_credentials/fadhel.ijlal@ceritanyaimel/adc.json was not found.; 283)
Traceback (most recent call last):
  File "/home/airflow/.local/lib/python3.10/site-packages/airflow/task/task_runner/standard_task_runner.py", line 117, in _start_by_fork
    ret = args.func(args, dag=self.dag)
  File "/home/airflow/.local/lib/python3.10/site-packages/airflow/cli/cli_config.py", line 49, in command
    return func(*args, **kwargs)
  File "/home/airflow/.local/lib/python3.10/site-packages/airflow/utils/cli.py", line 116, in wrapper
    return f(*args, **kwargs)
  File "/home/airflow/.local/lib/python3.10/site-packages/airflow/cli/commands/task_command.py", line 483, in task_run
    task_return_code = _run_task_by_selected_method(args, _dag, ti)
  File "/home/airflow/.local/lib/python3.10/site-packages/airflow/cli/commands/task_command.py", line 256, in _run_task_by_selected_method
    return _run_raw_task(args, ti)
  File "/home/airflow/.local/lib/python3.10/site-packages/airflow/cli/commands/task_command.py", line 341, in _run_raw_task
    return ti._run_raw_task(
  File "/home/airflow/.local/lib/python3.10/site-packages/airflow/utils/session.py", line 97, in wrapper
    return func(*args, session=session, **kwargs)
  File "/home/airflow/.local/lib/python3.10/site-packages/airflow/models/taskinstance.py", line 3005, in _run_raw_task
    return _run_raw_task(
  File "/home/airflow/.local/lib/python3.10/site-packages/airflow/models/taskinstance.py", line 273, in _run_raw_task
    TaskInstance._execute_task_with_callbacks(
  File "/home/airflow/.local/lib/python3.10/site-packages/airflow/models/taskinstance.py", line 3159, in _execute_task_with_callbacks
    result = self._execute_task(context, task_orig)
  File "/home/airflow/.local/lib/python3.10/site-packages/airflow/models/taskinstance.py", line 3183, in _execute_task
    return _execute_task(self, context, task_orig)
  File "/home/airflow/.local/lib/python3.10/site-packages/airflow/models/taskinstance.py", line 767, in _execute_task
    result = _execute_callable(context=context, **execute_callable_kwargs)
  File "/home/airflow/.local/lib/python3.10/site-packages/airflow/models/taskinstance.py", line 733, in _execute_callable
    return ExecutionCallableRunner(
  File "/home/airflow/.local/lib/python3.10/site-packages/airflow/utils/operator_helpers.py", line 252, in run
    return self.func(*args, **kwargs)
  File "/home/airflow/.local/lib/python3.10/site-packages/airflow/models/baseoperator.py", line 417, in wrapper
    return func(self, *args, **kwargs)
  File "/home/airflow/.local/lib/python3.10/site-packages/airflow/decorators/base.py", line 266, in execute
    return_value = super().execute(context)
  File "/home/airflow/.local/lib/python3.10/site-packages/airflow/models/baseoperator.py", line 417, in wrapper
    return func(self, *args, **kwargs)
  File "/home/airflow/.local/lib/python3.10/site-packages/airflow/operators/python.py", line 238, in execute
    return_value = self.execute_callable()
  File "/home/airflow/.local/lib/python3.10/site-packages/airflow/operators/python.py", line 256, in execute_callable
    return runner.run(*self.op_args, **self.op_kwargs)
  File "/home/airflow/.local/lib/python3.10/site-packages/airflow/utils/operator_helpers.py", line 252, in run
    return self.func(*args, **kwargs)
  File "/opt/airflow/dags/experiments/dynamic_task_mapping_parralel_dag.py", line 25, in fetch_messages_from_bq
    client = bigquery.Client(project=BIGQUERY_CONN_ID)
  File "/home/airflow/.local/lib/python3.10/site-packages/google/cloud/bigquery/client.py", line 241, in __init__
    super(Client, self).__init__(
  File "/home/airflow/.local/lib/python3.10/site-packages/google/cloud/client/__init__.py", line 321, in __init__
    Client.__init__(
  File "/home/airflow/.local/lib/python3.10/site-packages/google/cloud/client/__init__.py", line 178, in __init__
    credentials, _ = google.auth.default(scopes=scopes)
  File "/home/airflow/.local/lib/python3.10/site-packages/google/auth/_default.py", line 659, in default
    credentials, project_id = checker()
  File "/home/airflow/.local/lib/python3.10/site-packages/google/auth/_default.py", line 652, in <lambda>
    lambda: _get_explicit_environ_credentials(quota_project_id=quota_project_id),
  File "/home/airflow/.local/lib/python3.10/site-packages/google/auth/_default.py", line 271, in _get_explicit_environ_credentials
    credentials, project_id = load_credentials_from_file(
  File "/home/airflow/.local/lib/python3.10/site-packages/google/auth/_default.py", line 114, in load_credentials_from_file
    raise exceptions.DefaultCredentialsError(
google.auth.exceptions.DefaultCredentialsError: File /opt/gcp/config/legacy_credentials/fadhel.ijlal@ceritanyaimel/adc.json was not found.
[2025-01-11T12:03:39.455+0000] {local_task_job_runner.py:266} INFO - Task exited with return code 1
[2025-01-11T12:03:39.691+0000] {taskinstance.py:3895} INFO - 0 downstream tasks scheduled from follow-on schedule check
[2025-01-11T12:03:39.698+0000] {local_task_job_runner.py:245} INFO - ::endgroup::
